Workbook

Sheet geo tag SL
A2: Manggis | B2: -7.570067 | C2: 110.61242

Sheet Jumlah SL
B2: Jumlah Kegiatan SL, data ter-up date | E2: =NOW() -> 46304.559
B3: Kab | C3: Desa | D3: Jumlah SL
B4: Boyolali | C4: Manggis | D4: =COUNTA(Manggis!P2:U2) -> 6
B5: Sragen | C5: Sukorejo | D5: =COUNTA(Sukorejo!H2:L2) -> 5
C6: Karangmalang | D6: =COUNTA(Kliwonan!H2:L2) -> 2
B7: Klaten | C7: Jotangan | D7: =COUNTA(Jotangan!H2:N2) -> 6
C8: Tawangrejo | D8: =COUNTA(Tawangrejo!H2:L2) -> 3
B9: Ngawi | C9: Geneng | D9: =COUNTA(Geneng!H2:L2) -> 5
B10: Madiun | C10: Kliwonan | D10: =COUNTA(Klumutan!H2:M2) -> 6

Sheet SRP Geneng Ngawi
A1: SRP Training Geneng,Ngawi | D1: 46160
A2: No | B2: Nama Lengkap | C2: Organisasi / Klp Tani / Alamat | D2: Usia | E2: Jenis Kelamin
A3: 1 | B3: Joko Waluyo | C3: Lurah | D3: Diatas 35 tahun | E3: Laki-laki
A4: 2 | B4: Azis | C4: Tani Makmur | D4: Diatas 35 tahun | E4: Laki-laki
A5: 3 | B5: Hariyono | C5: Rukun Makmur | D5: Diatas 35 tahun | E5: Laki-laki
A6: 4 | B6: Suyatno | C6: Rukun Makmur | D6: Diatas 35 tahun | E6: Laki-laki
A7: 5 | B7: Nursamudin | C7: Sido Mulyo | D7: Diatas 35 tahun | E7: Laki-laki
A8: 6 | B8: Ibnu P. | C8: Sejahtera | D8: Diatas 35 tahun | E8: Laki-laki
A9: 7 | B9: Kaseri | C9: Margo Tani | D9: Diatas 35 tahun | E9: Laki-laki
A10: 8 | B10: Suharto | C10: Sejahtera | D10: Diatas 35 tahun | E10: Laki-laki
A11: 9 | B11: Sarijan | C11: Sejahtera | D11: Diatas 35 tahun | E11: Laki-laki
A12: 10 | B12: Purnomo | C12: Sejahtera | D12: Diatas 35 tahun | E12: Laki-laki
A13: 11 | B13: Warsono | C13: Sejahtera | D13: Diatas 35 tahun | E13: Laki-laki
A14: 12 | B14: Nuri | C14: Tunas Makmur | D14: Diatas 35 tahun | E14: Laki-laki
... A34: 32 | B34: Romdhoni | C34: Sido Mulyo | D34: Diatas 35 tahun | E34: Laki-laki
B36: Sama / dibawah 35 tahun | C36: Perempuan | D36: =COUNTIFS($E$3:$E$34,C36,$D$3:$D$34,B36) -> 0
B37: Sama / dibawah 35 tahun | C37: Laki-laki | D37: =COUNTIFS($E$3:$E$34,C37,$D$3:$D$34,B37) -> 0
B38: Diatas 35 tahun | C38: Perempuan | D38: =COUNTIFS($E$3:$E$34,C38,$D$3:$D$34,B38) -> 6
B39: Diatas 35 tahun | C39: Laki-laki | D39: =COUNTIFS($E$3:$E$34,C39,$D$3:$D$34,B39) -> 26

Sheet SRP Karangmalang Sragen
A1: SRP Karangmalang, Sragen | D1: 46159
A2: No | B2: Nama Lengkap | C2: Organisasi / Klp Tani / Alamat | D2: Usia | E2: Jenis Kelamin
A3: 1 | B3: Sutarno | C3: Makmur 2 | D3: Diatas 35 tahun | E3: Laki-laki
A4: 2 | B4: Wiyono | C4: Makmur 2 | D4: Diatas 35 tahun | E4: Laki-laki
A5: 3 | B5: Suyoto | C5: Makmur 3 | D5: Diatas 35 tahun | E5: Laki-laki
A6: 4 | B6: Giyanto | C6: Makmur 1 | D6: Diatas 35 tahun | E6: Laki-laki
A7: 5 | B7: Sarwono | C7: Makmur 2 | D7: Diatas 35 tahun | E7: Laki-laki
A8: 6 | B8: Sutarno | C8: Makmur 3 | D8: Diatas 35 tahun | E8: Laki-laki
A9: 7 | B9: Sularyo | C9: Usaha Mulya | D9: Diatas 35 tahun | E9: Laki-laki
A10: 8 | B10: Sutrisno | C10: Makmur 2 | D10: Diatas 35 tahun | E10: Laki-laki
A11: 9 | B11: Sarjono | C11: Makmur 3 | D11: Diatas 35 tahun | E11: Laki-laki
A12: 10 | B12: Sarimin | C12: Makmur 2 | D12: Diatas 35 tahun | E12: Laki-laki
A13: 11 | B13: Jumbadi | C13: Makmur 2 | D13: Diatas 35 tahun | E13: Laki-laki
A14: 12 | B14: Sarman | C14: Makmur 3 | D14: Diatas 35 tahun | E14: Laki-laki
... A37: 35 | B37: Sutarmin | C37: Kader | D37: Diatas 35 tahun | E37: Laki-laki
B39: Sama / dibawah 35 tahun | C39: Perempuan | D39: =COUNTIFS($E$3:$E$37,C39,$D$3:$D$37,B39)-1 -> 1
B40: Sama / dibawah 35 tahun | C40: Laki-laki | D40: =COUNTIFS($E$3:$E$37,C40,$D$3:$D$37,B40) -> 0
B41: Diatas 35 tahun | C41: Perempuan | D41: =COUNTIFS($E$3:$E$37,C41,$D$3:$D$37,B41) -> 5
B42: Diatas 35 tahun | C42: Laki-laki | D42: =COUNTIFS($E$3:$E$37,C42,$D$3:$D$37,B42)-1 -> 27
B44: Rikolto | C44: 2

Sheet SRP Manggis Boyolali
A1: SRP Training Manggis, Boyolali | D1: 46035
A2: No | B2: Nama Lengkap | C2: Organisasi / Klp Tani / Alamat | D2: Usia | E2: Jenis Kelamin
A3: 1 | B3: Darobi | C3: Jambu Manggis | D3: Diatas 35 tahun | E3: Laki-laki
A4: 2 | B4: Joko Susilo | C4: Gapoktan | D4: Diatas 35 tahun | E4: Laki-laki
A5: 3 | B5: Sukari | C5: Bibis Rejo | D5: Diatas 35 tahun | E5: Laki-laki
A6: 4 | B6: Sumarto | C6: Tani Makmur | D6: Diatas 35 tahun | E6: Laki-laki
A7: 5 | B7: Sajinu | C7: Tani Makmur | D7: Diatas 35 tahun | E7: Laki-laki
A8: 6 | B8: Jarmanto | C8: Tani Makmur | D8: Diatas 35 tahun | E8: Laki-laki
A9: 7 | B9: Mujiono | C9: Mardi Makmur | D9: Diatas 35 tahun | E9: Laki-laki
A10: 8 | B10: Hartini | C10: Jambu Wetan | D10: Diatas 35 tahun | E10: Perempuan
A11: 9 | B11: Limayati | C11: Bibis Rejo | D11: Diatas 35 tahun | E11: Perempuan
A12: 10 | B12: Daryono | C12: Miliran | D12: Diatas 35 tahun | E12: Laki-laki
A13: 11 | B13: Khoirul Fuad | C13: Dawar | D13: Diatas 35 tahun | E13: Laki-laki
A14: 12 | B14: Nur Sahid | C14: Dawar | D14: Diatas 35 tahun | E14: Laki-laki
... A29: 27 | B29: Ratih Rahmawati | C29: Rikolto | D29: Sama / dibawah 35 tahun | E29: Perempuan
B32: Sama / dibawah 35 tahun | C32: Perempuan | D32: =COUNTIFS($E$3:$E$37,C32,$D$3:$D$37,B32)-1 -> 1
B33: Sama / dibawah 35 tahun | C33: Laki-laki | D33: =COUNTIFS($E$3:$E$37,C33,$D$3:$D$37,B33) -> 0
B34: Diatas 35 tahun | C34: Perempuan | D34: =COUNTIFS($E$3:$E$37,C34,$D$3:$D$37,B34) -> 7
B35: Diatas 35 tahun | C35: Laki-laki | D35: =COUNTIFS($E$3:$E$37,C35,$D$3:$D$37,B35)-2 -> 16
D36: =SUM(D32:D35) -> 24
B37: Rikolto 3 peserta

Sheet SRP Bangak Boyolali 
A1: Training SRP Bangak, Boyolali | E1: 7 Mei 26
A2: No | B2: Nama Lengkap | C2: Organisasi / Klp Tani / Alamat | D2: NoHP | E2: Usia | F2: Jenis Kelamin
A3: 1 | B3: Bibit Harjo | C3: Gapoktan | E3: Diatas 35 tahun | F3: Laki-laki
A4: 2 | B4: Rajiman | C4: Gapoktan | E4: Diatas 35 tahun | F4: Laki-laki
A5: 3 | B5: Tono | C5: Gapoktan | E5: Diatas 35 tahun | F5: Laki-laki
A6: 4 | B6: Dalmamin | C6: Gapoktan | E6: Diatas 35 tahun | F6: Laki-laki
A7: 5 | B7: Sumardi | C7: Sanggrahan | E7: Diatas 35 tahun | F7: Laki-laki
A8: 6 | B8: Kasiman | C8: Sanggrahan | E8: Diatas 35 tahun | F8: Laki-laki
A9: 7 | B9: Yusuf M | C9: Gapotan Golah | E9: Diatas 35 tahun | F9: Laki-laki
A10: 8 | B10: Bambang | C10: Trayu | E10: Diatas 35 tahun | F10: Laki-laki
A11: 9 | B11: Wagiman | C11: Trayu | E11: Diatas 35 tahun | F11: Laki-laki
A12: 10 | B12: Dalmadi | C12: Tompen | E12: Diatas 35 tahun | F12: Laki-laki
A13: 11 | B13: Wiro Sudarmo | C13: Gabaran | E13: Diatas 35 tahun | F13: Laki-laki
A14: 12 | B14: Setriyana | C14: Perpabi | E14: Diatas 35 tahun | F14: Laki-laki
... A19: 17 | B19: Suraji | C19: Manukan | E19: Diatas 35 tahun | F19: Laki-laki
A20: 18 | B20: Mulyono | C20: Kembang Tani | D20: 813421950 | E20: Diatas 35 tahun | F20: Laki-laki
A21: 19 | B21: Wiryo | C21: Kembang Tani | E21: Diatas 35 tahun | F21: Laki-laki
A22: 20 | B22: Nuradin | C22: Kembang Tani | E22: Diatas 35 tahun | F22: Laki-laki
A23: 21 | B23: Yulianto | C23: Kembang Tani | E23: Diatas 35 tahun | F23: Laki-laki
A24: 22 | B24: Bejonyono | C24: Kembang Tani | D24: 83290610 | E24: Diatas 35 tahun | F24: Laki-laki
A25: 23 | B25: Siti Zubaidah | C25: BPP Banyudono | D25: 85642090075 | E25: Diatas 35 tahun | F25: Perempuan
A26: 24 | B26: Sutarti | C26: BPP Banyudono | E26: Diatas 35 tahun | F26: Perempuan
A27: 25 | B27: Wiwik Yuni A | C27: BPP Banyudono | E27: Diatas 35 tahun | F27: Perempuan
A28: 26 | B28: Anita Purwandani | C28: BPP Banyudono | E28: Diatas 35 tahun | F28: Perempuan
A29: 27 | B29: Sartono | C29: BPP Banyudono | E29: Diatas 35 tahun | F29: Laki-laki
A30: 28 | B30: Widodo | C30: BPP Banyudono | E30: Diatas 35 tahun | F30: Laki-laki
A31: 29 | B31: Widodo | C31: Pemdes | E31: Diatas 35 tahun | F31: Laki-laki
A32: 30 | B32: Parmin | C32: Petani | E32: Diatas 35 tahun | F32: Laki-laki
A33: 31 | B33: Sudali | C33: Pengairan | E33: Diatas 35 tahun | F33: Laki-laki
A34: 32 | B34: Selamet | C34: Poktan | E34: Diatas 35 tahun | F34: Laki-laki
A35: 33 | B35: Gundi | C35: Poktan | E35: Diatas 35 tahun | F35: Laki-laki
A36: 34 | B36: Sriyono | C36: Poktan | E36: Diatas 35 tahun | F36: Laki-laki
A37: 35 | B37: Ratih Rahmawati | C37: Rikolto | E37: Sama / dibawah 35 tahun | F37: Perempuan
B40: Sama / dibawah 35 tahun | C40: Perempuan | D40: =COUNTIFS($F$3:$F$37,C40,$E$3:$E$37,B40)-1 -> 0
B41: Sama / dibawah 35 tahun | C41: Laki-laki | D41: =COUNTIFS($F$3:$F$37,C41,$E$3:$E$37,B41) -> 0
B42: Diatas 35 tahun | C42: Perempuan | D42: =COUNTIFS($F$3:$F$37,C42,$E$3:$E$37,B42) -> 4
B43: Diatas 35 tahun | C43: Laki-laki | D43: =COUNTIFS($F$3:$F$37,C43,$E$3:$E$37,B43) -> 30
D44: =SUM(D40:D43) -> 34
B46: Rikolto 1 peserta

Sheet SRP Sumber Boyolali
A1: Training SRP Sumber, Kec Simo Kab. Boyolali | E1: 10 Mei 26
A2: No | B2: Nama Lengkap | C2: Organisasi / Klp Tani / Alamat | D2: 10 Mei Pelatihan SRP | E2: Usia | F2: Jenis Kelamin
A3: 1 | B3: Sabihis | C3: Ngudi Rejeki | D3: 83228628766 | E3: Diatas 35 tahun | F3: Laki-laki
A4: 2 | B4: M. Nur | C4: Babinsa | D4: 82135861383 | E4: Diatas 35 tahun | F4: Laki-laki
A5: 3 | B5: Sutono | C5: Nguri Subur | D5: 852293198 | E5: Diatas 35 tahun | F5: Laki-laki
A6: 4 | B6: Winaryo | C6: Poktan | E6: Diatas 35 tahun | F6: Laki-laki
A7: 5 | B7: Maemunah | C7: Poktan | E7: Diatas 35 tahun | F7: Perempuan
A8: 6 | B8: Ratih R | C8: Rikolto | D8: 85802138480 | E8: Sama / dibawah 35 tahun | F8: Perempuan
A9: 7 | B9: Juwarno Ahmad | C9: Ngudi Subur | E9: Diatas 35 tahun | F9: Laki-laki
A10: 8 | B10: Misnan | C10: Ngudi Subur | E10: Diatas 35 tahun | F10: Laki-laki
A11: 9 | B11: Muklas | C11: Ngudi Subur | E11: Diatas 35 tahun | F11: Laki-laki
A12: 10 | B12: Abdul Tholib | C12: Ngudi Subur | E12: Diatas 35 tahun | F12: Laki-laki
A13: 11 | B13: M. Ihsanudin | C13: Ngudi Subur | E13: Diatas 35 tahun | F13: Laki-laki
A14: 12 | B14: Sarni | C14: Ngudi Subur | E14: Diatas 35 tahun | F14: Laki-laki
A15: 13 | B15: Ngadeno | C15: Ngudi Subur | E15: Diatas 35 tahun | F15: Laki-laki
A16: 14 | B16: Muslih | C16: Ngudi Subur | E16: Diatas 35 tahun | F16: Laki-laki
A17: 15 | B17: Mutholib | C17: Ngudi Subur | E17: Diatas 35 tahun | F17: Laki-laki
A18: 16 | B18: Suyani | C18: Ngudi Subur | E18: Diatas 35 tahun | F18: Perempuan
A19: 17 | B19: Sulastri | C19: Ngudi Subur | E19: Diatas 35 tahun | F19: Perempuan
A20: 18 | B20: Wati | C20: Ngudi Subur | E20: Diatas 35 tahun | F20: Perempuan
... A38: 36 | B38: Wardi | C38: Tariwetan | E38: Diatas 35 tahun | F38: Laki-laki
B41: Sama / dibawah 35 tahun | C41: Perempuan | D41: =COUNTIFS($F$3:$F$38,C41,$E$3:$E$38,B41)-1 -> 0
B42: Sama / dibawah 35 tahun | C42: Laki-laki | D42: =COUNTIFS($F$3:$F$38,C42,$E$3:$E$38,B42) -> 0
B43: Diatas 35 tahun | C43: Perempuan | D43: =COUNTIFS($F$3:$F$38,C43,$E$3:$E$38,B43) -> 7
B44: Diatas 35 tahun | C44: Laki-laki | D44: =COUNTIFS($F$3:$F$38,C44,$E$3:$E$38,B44) -> 28
D45: =SUM(D41:D44) -> 35
B46: Rikolto 1 peserta

Sheet SRP Sukorejo Sragen
A1: Training SRP Sukorejo Sragen | D1: 46037
A2: No | B2: Nama Lengkap | C2: Organisasi / Klp Tani / Alamat | D2: Usia | E2: Jenis Kelamin
A3: 1 | B3: Sigit | C3: Karya Mandiri | D3: Diatas 35 tahun | E3: Laki-laki
A4: 2 | B4: Winarmo | C4: Karya Mandiri | D4: Diatas 35 tahun | E4: Laki-laki
A5: 3 | B5: Agung Widodo | C5: Margo Rukun II | D5: Diatas 35 tahun | E5: Laki-laki
A6: 4 | B6: Pujiwoyono | C6: Grenjengan | D6: Diatas 35 tahun | E6: Laki-laki
A7: 5 | B7: Padmo | C7: Plalangan | D7: Diatas 35 tahun | E7: Laki-laki
A8: 6 | B8: Karni | C8: Plalangan | D8: Diatas 35 tahun | E8: Laki-laki
A9: 7 | B9: Sumarno | C9: Sukorejo | D9: Diatas 35 tahun | E9: Laki-laki
A10: 8 | B10: Andri | C10: Plalangan | D10: Diatas 35 tahun | E10: Laki-laki
A11: 9 | B11: Harmoko | C11: Gemah Ripah | D11: Diatas 35 tahun | E11: Laki-laki
A12: 10 | B12: Sadi | C12: Pakis (Margowunung) | D12: Diatas 35 tahun | E12: Laki-laki
A13: 11 | B13: Hartini | C13: Pakis (Margowunung) | D13: Diatas 35 tahun | E13: Perempuan
A14: 12 | B14: Novika | C14: Karangjati | D14: Sama / dibawah 35 tahun | E14: Perempuan
... A36: 34 | B36: Danang Tri W | C36: Rikolto | D36: Diatas 35 tahun | E36: Laki-laki
B39: Sama / dibawah 35 tahun | C39: Perempuan | D39: =COUNTIFS($E$3:$E$36,C39,$D$3:$D$36,B39)-1 -> 1
B40: Sama / dibawah 35 tahun | C40: Laki-laki | D40: =COUNTIFS($E$3:$E$36,C40,$D$3:$D$36,B40) -> 0
B41: Diatas 35 tahun | C41: Perempuan | D41: =COUNTIFS($E$3:$E$36,C41,$D$3:$D$36,B41) -> 3
B42: Diatas 35 tahun | C42: Laki-laki | D42: =COUNTIFS($E$3:$E$36,C42,$D$3:$D$36,B42)-1 -> 28
D43: =SUM(D39:D42) -> 32
B44: Rikolto 2 peserta

Sheet SRP Kliwonan Sragen
A1: SRP Training Kliwonan Stagen | D1: 46140
A2: No | B2: Nama Lengkap | C2: Organisasi / Klp Tani / Alamat | D2: Usia | E2: Jenis Kelamin
A3: 1 | B3: Widodo | C3: Kliwonan | D3: Diatas 35 tahun | E3: Laki-laki
A4: 2 | B4: Surono | C4: Kliwonan | D4: Diatas 35 tahun | E4: Laki-laki
A5: 3 | B5: Gimin M | C5: Kliwonan | D5: Diatas 35 tahun | E5: Laki-laki
A6: 4 | B6: Tarno | C6: Kuyang | D6: Diatas 35 tahun | E6: Laki-laki
A7: 5 | B7: Wakit | C7: JokoTaniII | D7: Diatas 35 tahun | E7: Laki-laki
A8: 6 | B8: Slamet Widodo | C8: Kliwonan | D8: Diatas 35 tahun | E8: Laki-laki
A9: 7 | B9: Warsito | C9: Kliwonan | D9: Diatas 35 tahun | E9: Laki-laki
A10: 8 | B10: Slamet Riyono | C10: Kliwonan | D10: Diatas 35 tahun | E10: Laki-laki
A11: 9 | B11: Sriyono | C11: Kuyang | D11: Diatas 35 tahun | E11: Laki-laki
A12: 10 | B12: Sukimin | C12: Kuyang | D12: Diatas 35 tahun | E12: Laki-laki
A13: 11 | B13: Suprapto | C13: Kliwonan | D13: Diatas 35 tahun | E13: Laki-laki
A14: 12 | B14: Sujatno | C14: Kliwonan | D14: Diatas 35 tahun | E14: Laki-laki
... A37: 35 | B37: Dwi Rejeki | C37: PPL | D37: Diatas 35 tahun | E37: Perempuan
B40: Sama / dibawah 35 tahun | C40: Perempuan | D40: =COUNTIFS($E$3:$E$37,C40,$D$3:$D$37,B40)-1 -> 0
B41: Sama / dibawah 35 tahun | C41: Laki-laki | D41: =COUNTIFS($E$3:$E$37,C41,$D$3:$D$37,B41) -> 0
B42: Diatas 35 tahun | C42: Perempuan | D42: =COUNTIFS($E$3:$E$37,C42,$D$3:$D$37,B42) -> 6
B43: Diatas 35 tahun | C43: Laki-laki | D43: =COUNTIFS($E$3:$E$37,C43,$D$3:$D$37,B43) -> 28
D44: =SUM(D40:D43) -> 34
B45: Rikolto 1 peserta

Sheet SRP Jotangan Boyolali
A1: Training SRP Jotangan Klaten | E1: 12 Mei 26
A2: No | B2: Nama Lengkap | C2: Organisasi / Klp Tani / Alamat | D2: 12 Mei Pelatihan SRP - Jarwo | E2: Usia | F2: Jenis Kelamin
A3: 1 | B3: Widada | C3: Mekarsari | E3: Diatas 35 tahun | F3: Laki-laki
A4: 2 | B4: Suratno | C4: Mekarsari | E4: Diatas 35 tahun | F4: Laki-laki
A5: 3 | B5: Suparno | C5: Mekarsari | E5: Diatas 35 tahun | F5: Laki-laki
A6: 4 | B6: Ranto | C6: Mekarsari | E6: Diatas 35 tahun | F6: Laki-laki
A7: 5 | B7: Sutarman | C7: Mekarsari | E7: Diatas 35 tahun | F7: Laki-laki
A8: 6 | B8: Harmin | C8: Mekarsari | E8: Diatas 35 tahun | F8: Laki-laki
A9: 7 | B9: Siswanto | C9: Mekarsari | E9: Diatas 35 tahun | F9: Laki-laki
A10: 8 | B10: Supriyanta | C10: Mekarsari | E10: Diatas 35 tahun | F10: Laki-laki
A11: 9 | B11: Sukarman | C11: Mekarsari | E11: Diatas 35 tahun | F11: Laki-laki
A12: 10 | B12: Wariso | C12: Mekarsari | E12: Diatas 35 tahun | F12: Laki-laki
A13: 11 | B13: Suparjo | C13: Mekarsari | E13: Diatas 35 tahun | F13: Laki-laki
A14: 12 | B14: Suminah | C14: Mekarsari | E14: Diatas 35 tahun | F14: Perempuan
... A35: 33 | B35: Galang S | C35: Mekarsari | E35: Diatas 35 tahun | F35: Laki-laki
B37: Sama / dibawah 35 tahun | C37: Perempuan | E37: =COUNTIFS($F$3:$F$35,C37,$E$3:$E$35,B37) -> 0
B38: Sama / dibawah 35 tahun | C38: Laki-laki | E38: =COUNTIFS($F$3:$F$35,C38,$E$3:$E$35,B38) -> 0
B39: Diatas 35 tahun | C39: Perempuan | E39: =COUNTIFS($F$3:$F$35,C39,$E$3:$E$35,B39) -> 5
B40: Diatas 35 tahun | C40: Laki-laki | E40: =COUNTIFS($F$3:$F$35,C40,$E$3:$E$35,B40) -> 28
E41: =SUM(E37:E40) -> 33

Sheet SRP Klumutan Madiun
A1: Training SRP Klumutan Madiun | E1: 19 Mei 26
A2: No | B2: Nama Lengkap | C2: Organisasi / Klp Tani / Alamat | D2: No HP | E2: Usia | F2: Jenis Kelamin
A3: 1 | B3: Karno | C3: Tani Makmur | D3: 85740645408 | E3: Diatas 35 tahun | F3: Laki-laki
A4: 2 | B4: Dani Anibya | C4: Tani Makmur | D4: 88896295403 | E4: Sama / dibawah 35 tahun | F4: Laki-laki
A5: 3 | B5: Gunadi | C5: Mbruwok Makmur | D5: 82145566267 | E5: Diatas 35 tahun | F5: Laki-laki
A6: 4 | B6: Sukardiono | C6: Tani Makmur | D6: 85602746607 | E6: Diatas 35 tahun | F6: Laki-laki
A7: 5 | B7: Wisnu TM | C7: Kader Madiun | D7: 82230302933 | E7: Diatas 35 tahun | F7: Laki-laki
A8: 6 | B8: Damanto | C8: PPL | D8: 8123108316 | E8: Diatas 35 tahun | F8: Laki-laki
A9: 7 | B9: Joko Mardi P | C9: Tani Rejo | D9: 81022576256 | E9: Diatas 35 tahun | F9: Laki-laki
A10: 8 | B10: Mardi | C10: Tani Rejo | D10: - | E10: Diatas 35 tahun | F10: Laki-laki
A11: 9 | B11: Anung B. | C11: Tani Rejo | D11: 8224568973 | E11: Sama / dibawah 35 tahun | F11: Laki-laki
A12: 10 | B12: Priyono | C12: Tani Makmur | D12: 81339989911 | E12: Diatas 35 tahun | F12: Laki-laki
A13: 11 | B13: Yanto | C13: Tani Makmur | D13: 85745417546 | E13: Diatas 35 tahun | F13: Laki-laki
A14: 12 | B14: Ratih R | C14: Rikolto | D14: 85802138486 | E14: Sama / dibawah 35 tahun | F14: Perempuan
A15: 13 | B15: Yuni Astuti | C15: KWT Larasati | D15: 82257433691 | E15: Diatas 35 tahun | F15: Perempuan
A16: 14 | B16: Suntari | C16: KWT Larasati | D16: 81933046457 | E16: Diatas 35 tahun | F16: Perempuan
A17: 15 | B17: Supriyanto | C17: Mekar Sari | D17: 82858577279 | E17: Diatas 35 tahun | F17: Laki-laki
A18: 16 | B18: Mariadi | C18: Mekar Sari | D18: 85773201878 | E18: Diatas 35 tahun | F18: Laki-laki
A19: 17 | B19: Gunawan | C19: Tani Makmur | D19: 81239880241 | E19: Diatas 35 tahun | F19: Laki-laki
A20: 18 | B20: Puryanto | C20: Tani Makmur | D20: 81230979144 | E20: Diatas 35 tahun | F20: Laki-laki
A21: 19 | B21: Wanda S.N | C21: Tani Makmur | D21: 85708061696 | E21: Sama / dibawah 35 tahun | F21: Perempuan
A22: 20 | B22: Rudy Ristanto | C22: Tani Makmur | D22: 87888076699 | E22: Diatas 35 tahun | F22: Laki-laki
A23: 21 | B23: Mariyono | C23: Tani Makmur | D23: 81346283838 | E23: Diatas 35 tahun | F23: Laki-laki
A24: 22 | B24: Utomo | C24: Tani Makmur | D24: - | E24: Diatas 35 tahun | F24: Laki-laki
A25: 23 | B25: Eko Supriyono | C25: Tani Makmur | D25: 87840808652 | E25: Diatas 35 tahun | F25: Laki-laki
A26: 24 | B26: Gunawan N | C26: Tani Makmur | D26: 87716137574 | E26: Diatas 35 tahun | F26: Laki-laki
A27: 25 | B27: Andika P. | C27: Tani Makmur | D27: 85748645412 | E27: Diatas 35 tahun | F27: Laki-laki
A28: 26 | B28: Juri | C28: Tani Makmur | D28: 89523429420927 | E28: Diatas 35 tahun | F28: Laki-laki
A29: 27 | B29: Marto | C29: Mbruwok Makmur | D29: 81254097800 | E29: Diatas 35 tahun | F29: Laki-laki
B31: Sama / dibawah 35 tahun | C31: Perempuan | D31: =COUNTIFS($F$3:$F$29,C31,$E$3:$E$29,B31)-1 -> 1
B32: Sama / dibawah 35 tahun | C32: Laki-laki | D32: =COUNTIFS($F$3:$F$29,C32,$E$3:$E$29,B32) -> 2
B33: Diatas 35 tahun | C33: Perempuan | D33: =COUNTIFS($F$3:$F$29,C33,$E$3:$E$29,B33) -> 2
B34: Diatas 35 tahun | C34: Laki-laki | D34: =COUNTIFS($F$3:$F$29,C34,$E$3:$E$29,B34) -> 21
D35: =SUM(D31:D34) -> 26

Sheet SRP Pogung Klaten
A1: Training SRP Pogung Klaten | E1: 46197
A2: No | B2: Nama Lengkap | C2: Organisasi / Klp Tani / Alamat | D2: No HP | E2: Usia | F2: Jenis Kelamin
A3: 1 | B3: Sri Sudarmi | C3: Brengkungan | E3: Diatas 35 tahun | F3: Perempuan
A4: 2 | B4: Sri Widadi | C4: Soka Alas | E4: Diatas 35 tahun | F4: Perempuan
A5: 3 | B5: Semi Rahayu | C5: Brengkungan | E5: Diatas 35 tahun | F5: Perempuan
A6: 4 | B6: Sriyono | C6: Brengkungan | E6: Diatas 35 tahun | F6: Laki-laki
A7: 5 | B7: Sri Tentrem | C7: Brengkungan | E7: Diatas 35 tahun | F7: Perempuan
A8: 6 | B8: Tukmini | C8: Ngalihan | E8: Diatas 35 tahun | F8: Perempuan
A9: 7 | B9: Wiji | C9: Tegal | E9: Diatas 35 tahun | F9: Perempuan
A10: 8 | B10: Sugitto | C10: Brengkungan | E10: Diatas 35 tahun | F10: Laki-laki
A11: 9 | B11: Marmo | C11: Brengkungan | E11: Diatas 35 tahun | F11: Laki-laki
A12: 10 | B12: Limhar | C12: Niten | E12: Diatas 35 tahun | F12: Laki-laki
A13: 11 | B13: Priyomulyono | C13: Niten | E13: Diatas 35 tahun | F13: Laki-laki
A14: 12 | B14: Gito Andik | C14: Brengkungan | E14: Diatas 35 tahun | F14: Laki-laki
... A35: 33 | B35: Ratih | C35: Rikolto | E35: Sama / dibawah 35 tahun | F35: Perempuan
B37: Sama / dibawah 35 tahun | C37: Perempuan | D37: =COUNTIFS($F$3:$F$35,C37,$E$3:$E$35,B37)-1 -> 0
B38: Sama / dibawah 35 tahun | C38: Laki-laki | D38: =COUNTIFS($F$3:$F$35,C38,$E$3:$E$35,B38) -> 0
B39: Diatas 35 tahun | C39: Perempuan | D39: =COUNTIFS($F$3:$F$35,C39,$E$3:$E$35,B39) -> 8
B40: Diatas 35 tahun | C40: Laki-laki | D40: =COUNTIFS($F$3:$F$35,C40,$E$3:$E$35,B40) -> 24
D41: =SUM(D37:D40) -> 32

Sheet SRP Mojo Boyolali
A1: Training SRP Pogung Klaten | E1: 46197
A2: No | B2: Nama Lengkap | C2: Organisasi / Klp Tani / Alamat | D2: No HP | E2: Usia | F2: Jenis Kelamin
A3: 1 | B3: Joko Widodo | C3: Usaha Makmur I | E3: Diatas 35 tahun | F3: Laki-laki
A4: 2 | B4: M. Baidlowi M | C4: Usaha Makmur 2 | E4: Diatas 35 tahun | F4: Laki-laki
A5: 3 | B5: Kelik Purnomo | C5: Usaha Makmur 2 | E5: Diatas 35 tahun | F5: Laki-laki
A6: 4 | B6: Yatmo | C6: Sumber Makmur | E6: Diatas 35 tahun | F6: Laki-laki
A7: 5 | B7: Nurrohim | C7: Jati Mulya | E7: Diatas 35 tahun | F7: Laki-laki
A8: 6 | B8: A. Imroni | C8: Jati Mulya | E8: Diatas 35 tahun | F8: Laki-laki
A9: 7 | B9: Sunardi | C9: Gemah Ripah | E9: Diatas 35 tahun | F9: Laki-laki
A10: 8 | B10: Sujud H. | C10: Gemah Ripah | E10: Diatas 35 tahun | F10: Laki-laki
A11: 9 | B11: Mitro | C11: Usaha Makmur 1 | E11: Diatas 35 tahun | F11: Laki-laki
A12: 10 | B12: Ngatno | C12: Berkah | E12: Diatas 35 tahun | F12: Laki-laki
A13: 11 | B13: Mulyadi | C13: Jati Mulyo | E13: Diatas 35 tahun | F13: Laki-laki
A14: 12 | B14: Ismadi | C14: Berkah | E14: Diatas 35 tahun | F14: Laki-laki
... A36: 34 | B36: Ratih | C36: Rikolto | E36: Sama / dibawah 35 tahun | F36: Perempuan
B38: Sama / dibawah 35 tahun | C38: Perempuan | D38: =COUNTIFS($F$3:$F$36,C38,$E$3:$E$36,B38)-1 -> 0
B39: Sama / dibawah 35 tahun | C39: Laki-laki | D39: =COUNTIFS($F$3:$F$36,C39,$E$3:$E$36,B39) -> 0
B40: Diatas 35 tahun | C40: Perempuan | D40: =COUNTIFS($F$3:$F$36,C40,$E$3:$E$36,B40) -> 8
B41: Diatas 35 tahun | C41: Laki-laki | D41: =COUNTIFS($F$3:$F$36,C41,$E$3:$E$36,B41) -> 25
D42: =SUM(D38:D41) -> 33

Sheet SRP Bahat Klaten
A1: Training SRP Pogung Klaten | E1: 46197
A2: No | B2: Nama Lengkap | C2: Organisasi / Klp Tani / Alamat | D2: No HP | E2: Usia | F2: Jenis Kelamin
A3: 1 | B3: Wito | C3: Sri Rejeki | E3: Diatas 35 tahun | F3: Laki-laki
A4: 2 | B4: Nyata | C4: Sedyo Mulyo | D4: 8156707218 | E4: Diatas 35 tahun | F4: Laki-laki
A5: 3 | B5: Saliman | C5: Sedyo Mulyo | D5: 8587898981 | E5: Diatas 35 tahun | F5: Laki-laki
A6: 4 | B6: Sumar | C6: Sedyo Mulyo | E6: Diatas 35 tahun | F6: Laki-laki
A7: 5 | B7: Maryana | C7: Sedyo Mulyo | E7: Diatas 35 tahun | F7: Laki-laki
A8: 6 | B8: Harda | C8: Sedyo Mulyo | E8: Diatas 35 tahun | F8: Laki-laki
A9: 7 | B9: S. Darya | C9: Sedyo Mulyo | E9: Diatas 35 tahun | F9: Laki-laki
A10: 8 | B10: Lamta | C10: Sedyo Mulyo | E10: Diatas 35 tahun | F10: Laki-laki
A11: 9 | B11: Bagiyo | C11: Sedyo Mulyo | D11: 85926590886 | E11: Diatas 35 tahun | F11: Laki-laki
A12: 10 | B12: Suyadi | C12: Sedyo Mulyo | E12: Diatas 35 tahun | F12: Laki-laki
A13: 11 | B13: Suyadi D.G. | C13: Sri Rejeki | E13: Diatas 35 tahun | F13: Laki-laki
A14: 12 | B14: Taryana | C14: Sri Rejeki | E14: Diatas 35 tahun | F14: Laki-laki
A15: 13 | B15: Sudiman | C15: Sri Rejeki | E15: Diatas 35 tahun | F15: Laki-laki
A16: 14 | B16: Maksum | C16: Sri Rejeki | E16: Diatas 35 tahun | F16: Laki-laki
A17: 15 | B17: Sunarno | C17: Sri Rejeki | E17: Diatas 35 tahun | F17: Laki-laki
A18: 16 | B18: Retno Umi N | C18: PPL Bayat | D18: 81807796167 | E18: Diatas 35 tahun | F18: Perempuan
A19: 17 | B19: Muhson Burhani | C19: PPL Bayat | D19: 85725376161 | E19: Diatas 35 tahun | F19: Laki-laki
A20: 18 | B20: M. Bahrudin | C20: PPL Bayat | D20: 85725984779 | E20: Diatas 35 tahun | F20: Laki-laki
A21: 19 | B21: Arus Purwanto | C21: KWT Bayat | E21: Diatas 35 tahun | F21: Laki-laki
A22: 20 | B22: Budi Sulistiyo | C22: PPL Bayat | D22: 85642119229 | E22: Diatas 35 tahun | F22: Laki-laki
A23: 21 | B23: Kasiyem | C23: Sri Rejeki | E23: Diatas 35 tahun | F23: Laki-laki
A24: 22 | B24: Slamet | C24: Sri Rejeki | E24: Diatas 35 tahun | F24: Laki-laki
A25: 23 | B25: Ratih Rahmawati | C25: Rikolto | D25: 85802138480 | E25: Sama / dibawah 35 tahun | F25: Perempuan
A26: 24 | B26: Ngadimin | C26: Sri Rejeki | E26: Diatas 35 tahun | F26: Laki-laki
A27: 25 | B27: Wandi | C27: Sedyo Mulyo | E27: Diatas 35 tahun | F27: Laki-laki
A28: 26 | B28: Sugito | C28: Sri Rejeki | E28: Diatas 35 tahun | F28: Laki-laki
A29: 27 | B29: Ngadimin | C29: Sedyo Mulyo | E29: Diatas 35 tahun | F29: Laki-laki
A30: 28 | B30: Jumiyem | C30: Mekar Sari | E30: Diatas 35 tahun | F30: Perempuan
A31: 29 | B31: Lagiyem | C31: Mekar Sari | E31: Diatas 35 tahun | F31: Perempuan
A32: 30 | B32: Irub | C32: Mekar Sari | E32: Diatas 35 tahun | F32: Perempuan
A33: 31 | B33: Warsini | C33: Mekar Sari | E33: Diatas 35 tahun | F33: Perempuan
A34: 32 | B34: Suwarni | C34: Mekar Sari | E34: Diatas 35 tahun | F34: Perempuan
A35: 33 | B35: Tentrem | C35: Mekar Sari | E35: Diatas 35 tahun | F35: Laki-laki
A36: 34 | B36: Samino | C36: Sedyo Mulyo | E36: Diatas 35 tahun | F36: Laki-laki
A37: 35 | B37: Suwarni | C37: Sri Rejeki | E37: Diatas 35 tahun | F37: Perempuan
... A40: 38 | B40: Wagiman | C40: Sri Rejeki | E40: Diatas 35 tahun | F40: Laki-laki
B44: Sama / dibawah 35 tahun | C44: Perempuan | D44: =COUNTIFS($F$3:$F$42,C44,$E$3:$E$42,B44)-1 -> 0
B45: Sama / dibawah 35 tahun | C45: Laki-laki | D45: =COUNTIFS($F$3:$F$42,C45,$E$3:$E$42,B45) -> 0
...

Sheet SRP Tawangrejo
A1: Training SRP Tawangrejo Klaten,16 Jul
A2: No | B2: Nama Lengkap | C2: Organisasi / Klp Tani / Alamat | D2: No HP | E2: Usia | F2: Jenis Kelamin
A3: 1 | B3: Krisdiyanto A | C3: POPT BPP Barat | E3: Diatas 35 tahun | F3: Laki-laki
A4: 2 | B4: Agung S | E4: Sama / dibawah 35 tahun | F4: Laki-laki
A5: 3 | B5: Sulardi | C5: Gapoktan | E5: Diatas 35 tahun | F5: Laki-laki
A6: 4 | B6: Tauni | C6: KWT Sakinah | E6: Diatas 35 tahun | F6: Laki-laki
A7: 5 | B7: Bahrudin | C7: BPP Bayat | E7: Diatas 35 tahun | F7: Laki-laki
A8: 6 | B8: Parjiyati | C8: KWT Sakinah | E8: Diatas 35 tahun | F8: Perempuan
A9: 7 | B9: Retno Umi N | C9: PPL Bayat | E9: Diatas 35 tahun | F9: Perempuan
A10: 8 | B10: Muhson B | C10: PPL Bayat | E10: Diatas 35 tahun | F10: Laki-laki
A11: 9 | B11: Agus Purwanto | C11: PPL Bayat | E11: Diatas 35 tahun | F11: Laki-laki
A12: 10 | B12: Budi Sulistyo | C12: PPL Bayat | E12: Diatas 35 tahun | F12: Laki-laki
A13: 11 | B13: Widayatmi | C13: KWT Sakinah | E13: Diatas 35 tahun | F13: Perempuan
A14: 12 | B14: Suparno | C14: Mulya Makmur | E14: Diatas 35 tahun | F14: Laki-laki
A15: 13 | B15: Siswanto | C15: Mulya Makmur | E15: Diatas 35 tahun | F15: Laki-laki
A16: 14 | B16: Suparlan | C16: Mulya Makmur | E16: Diatas 35 tahun | F16: Laki-laki
... A28: 26 | B28: Suratno | C28: Mekarsari | E28: Diatas 35 tahun | F28: Laki-laki
A29: 27 | B29: Samina | C29: Gapoktan | D29: 81329999127 | E29: Diatas 35 tahun | F29: Perempuan
A30: 28 | B30: Sutinem | C30: Gapoktan | D30: 87884089984 | E30: Diatas 35 tahun | F30: Perempuan
A31: 29 | B31: Harbini S. | C31: Gapoktan | D31: 81233264425 | E31: Diatas 35 tahun | F31: Perempuan
A32: 30 | B32: Giyem | C32: Gapoktan | D32: 81226845492 | E32: Diatas 35 tahun | F32: Perempuan
A33: 31 | B33: Suyanto | C33: Gapoktan | D33: 85640519448 | E33: Diatas 35 tahun | F33: Laki-laki
A34: 32 | B34: Sadiman | C34: Gapoktan | E34: Diatas 35 tahun | F34: Laki-laki
A35: 33 | B35: Sucipto | C35: Gapoktan | E35: Diatas 35 tahun | F35: Laki-laki
A36: 34 | B36: Sagimin | C36: Gapoktan | E36: Diatas 35 tahun | F36: Laki-laki
A37: 35 | B37: Warsito | C37: Mekarsari | E37: Diatas 35 tahun | F37: Laki-laki
A38: 36 | B38: Dalimin | C38: Mekarsari | D38: 8127777691 | E38: Diatas 35 tahun | F38: Laki-laki
A39: 37 | B39: Saginoto Prayitno | C39: Mekarsari | E39: Diatas 35 tahun | F39: Laki-laki
A40: 38 | B40: Suwanto | C40: Mekarsari | D40: 82340012113 | E40: Diatas 35 tahun | F40: Laki-laki
A41: 39 | B41: Salimin | C41: Gagatan | E41: Diatas 35 tahun | F41: Laki-laki
A42: 40 | B42: Jarminto | C42: KTNA RN | D42: 81548355871 | E42: Diatas 35 tahun | F42: Laki-laki
A43: 41 | B43: Sugiyono | C43: KTNA Sri Mulyo | E43: Diatas 35 tahun | F43: Laki-laki
B46: Sama / dibawah 35 tahun | C46: Perempuan | D46: =COUNTIFS($F$3:$F$43,C46,$E$3:$E$43,B46) -> 0 | E46: Diatas 35 tahun
B47: Sama / dibawah 35 tahun | C47: Laki-laki | D47: =COUNTIFS($F$3:$F$43,C47,$E$3:$E$43,B47) -> 1 | E47: Diatas 35 tahun
B48: Diatas 35 tahun | C48: Perempuan | D48: =COUNTIFS($F$3:$F$43,C48,$E$3:$E$43,B48) -> 8 | E48: Diatas 35 tahun
B49: Diatas 35 tahun | C49: Laki-laki | D49: =COUNTIFS($F$3:$F$43,C49,$E$3:$E$43,B49) -> 32 | E49: Diatas 35 tahun
D50: =SUM(D46:D49) -> 41

Sheet SRP Sugihwaras
A1: Training SRP Sugihwaras Madiun,21 Jul | E1: 46197
A2: No | B2: Nama Lengkap | C2: Organisasi / Klp Tani / Alamat | D2: No HP | E2: Usia | F2: Jenis Kelamin
A3: 1 | B3: Heri Suparmanto | C3: Margo Mulyo | D3: 83845628805 | E3: Diatas 35 tahun | F3: Laki-laki
A4: 2 | B4: Paniran | C4: Margo Mulyo | E4: Diatas 35 tahun | F4: Laki-laki
A5: 3 | B5: Suparno | C5: Margo Prastyo | D5: 81220343407 | E5: Diatas 35 tahun | F5: Laki-laki
A6: 4 | B6: Parno | C6: Margo Mulyo | D6: 81252146528 | E6: Diatas 35 tahun | F6: Laki-laki
A7: 5 | B7: Priani | C7: Margo Rahayu | D7: 81341611421 | E7: Diatas 35 tahun | F7: Perempuan
A8: 6 | B8: Amirah | C8: Margo Rahayu | D8: 81335097396 | E8: Diatas 35 tahun | F8: Perempuan
A9: 7 | B9: Watini | C9: Margo Sari | D9: 85330381102 | E9: Diatas 35 tahun | F9: Perempuan
A10: 8 | B10: Widyawati | C10: Margo Utomo | E10: Diatas 35 tahun | F10: Perempuan
A11: 9 | B11: Sundari | C11: Margo Utomo | E11: Diatas 35 tahun | F11: Perempuan
A12: 10 | B12: Priyati | C12: Margo Sari | E12: Diatas 35 tahun | F12: Perempuan
A13: 11 | B13: Sulastri | C13: Gapoktan | E13: Diatas 35 tahun | F13: Perempuan
A14: 12 | B14: Djoko Sumi | C14: Margo Baru | D14: 87858857949 | E14: Diatas 35 tahun | F14: Laki-laki
A15: 13 | B15: Salam Haryono | C15: Margo Baru | E15: Diatas 35 tahun | F15: Laki-laki
A16: 14 | B16: Subari | C16: Margo Baru | E16: Diatas 35 tahun | F16: Laki-laki
A17: 15 | B17: Taman | C17: Gapoktan | D17: 81335481094 | E17: Diatas 35 tahun | F17: Laki-laki
A18: 16 | B18: Sutaji | C18: Margo Mulyo | D18: 82259864121 | E18: Diatas 35 tahun | F18: Laki-laki
A19: 17 | B19: Irkam | C19: Margo Kaloko | D19: 81230573372 | E19: Diatas 35 tahun | F19: Laki-laki
A20: 18 | B20: Munjari | C20: Margo Mulyo | D20: 8125952707 | E20: Diatas 35 tahun | F20: Laki-laki
A21: 19 | B21: Marsono | C21: Margo Mulyo | D21: 813575615764 | E21: Diatas 35 tahun | F21: Laki-laki
A22: 20 | B22: Sugiyono | C22: Margo Mulyo | D22: 81334609799 | E22: Diatas 35 tahun | F22: Laki-laki
A23: 21 | B23: Ciman | C23: Margo Mulyo | E23: Diatas 35 tahun | F23: Laki-laki
A24: 22 | B24: Giman | C24: Margo Mulyo | E24: Diatas 35 tahun | F24: Laki-laki
A25: 23 | B25: Joko | C25: Margo Mulyo | E25: Diatas 35 tahun | F25: Laki-laki
A26: 24 | B26: Barmotamin | C26: Margo Mulyo | E26: Diatas 35 tahun | F26: Laki-laki
A27: 25 | B27: Sukimin | C27: Margo Tani | E27: Diatas 35 tahun | F27: Laki-laki
A28: 26 | B28: Sumiran | C28: Margo Mulyo | E28: Diatas 35 tahun | F28: Laki-laki
A29: 27 | B29: Nyaman | C29: Margo Mulyo | E29: Diatas 35 tahun | F29: Laki-laki
A30: 28 | B30: Suwito | C30: Margo Utomo | E30: Diatas 35 tahun | F30: Laki-laki
A31: 29 | B31: Harjo Jamin | C31: Margo Utomo | D31: 81357357289 | E31: Diatas 35 tahun | F31: Laki-laki
A32: 30 | B32: Suyitno | C32: Margo Utomo | E32: Diatas 35 tahun | F32: Laki-laki
A33: 31 | B33: Sigit Raharjo | C33: Margo Mulyo | D33: 82244050359 | E33: Diatas 35 tahun | F33: Laki-laki
A34: 32 | B34: Wiko S. | C34: PPL | D34: 82143090283 | E34: Diatas 35 tahun | F34: Laki-laki
B37: Sama / dibawah 35 tahun | C37: Perempuan | D37: =COUNTIFS($F$3:$F$34,C37,$E$3:$E$34,B37) -> 0 | E37: Diatas 35 tahun
B38: Sama / dibawah 35 tahun | C38: Laki-laki | D38: =COUNTIFS($F$3:$F$34,C38,$E$3:$E$34,B38) -> 0 | E38: Diatas 35 tahun
B39: Diatas 35 tahun | C39: Perempuan | D39: =COUNTIFS($F$3:$F$34,C39,$E$3:$E$34,B39) -> 7 | E39: Diatas 35 tahun
B40: Diatas 35 tahun | C40: Laki-laki | D40: =COUNTIFS($F$3:$F$34,C40,$E$3:$E$34,B40) -> 25 | E40: Diatas 35 tahun
D41: =SUM(D37:D40) -> 32

Sheet indirect 2026
A1: No | B1: Nama Petani | C1: Poktan | D1: Desa | E1: Kecamatan
A2: 1 | B2: Pijiyatmi | C2: Golek Uppo | D2: Beji | E2: Andong
A3: 2 | B3: Nafikoh | C3: Golek Uppo | D3: Beji | E3: Andong
A4: 3 | B4: Fatonah | C4: Golek Uppo | D4: Beji | E4: Andong
A5: 4 | B5: Marimin | C5: Golek Uppo | D5: Beji | E5: Andong
A6: 5 | B6: Rujiyem | C6: Golek Uppo | D6: Beji | E6: Andong
A7: 6 | B7: Margiyanti | C7: Golek Uppo | D7: Beji | E7: Andong
A8: 7 | B8: Narti | C8: Golek Uppo | D8: Beji | E8: Andong
A9: 8 | B9: Sumiyem | C9: Golek Uppo | D9: Beji | E9: Andong
A10: 9 | B10: Ginah | C10: Golek Uppo | D10: Beji | E10: Andong
A11: 10 | B11: Sumiyatun | C11: Golek Uppo | D11: Beji | E11: Andong
A12: 11 | B12: Murdiyati | C12: Golek Uppo | D12: Beji | E12: Andong
A13: 12 | B13: Sukiman | C13: Golek Uppo | D13: Beji | E13: Andong
... A221: 220 | B221: Hariyanto | C221: Tani Utun | D221: Bongsopotro | E221: Saradan

Sheet Tab all
B2: Kabupaten | C2: Desa | D2: Kecamatan | E2: Farmers counted as unique name | F2: Participants who 80% attendance the SL | G2: Participants who 50% attendance the SL | H2: SL 1 | I2: SL 2 | J2: SL 3 | K2: SL 4 | L2: SL 5 | M2: SL 6 | P2: Training SRP | Q2: Jumlah Peserta | R2: Overlay dengan SL | S2: Petani peserta training tdk ikut SL | T2: Capaian petani | U2: =NOW() -> 46304.559
B3: Boyolali | C3: Manggis | D3: Mojosongo | E3: =COUNTA(Manggis!B3:B61)-1 -> 58 | F3: =Manggis!W65 -> 16 | G3: =Manggis!W66 -> 21 | H3: =Manggis!P63-1 -> 26 | I3: =Manggis!Q63-1 -> 31 | J3: =Manggis!R63-1 -> 36 | K3: =Manggis!S63 -> 18 | L3: =Manggis!T63-1 -> 28 | M3: =Manggis!U63-1 -> 34 | O3: Boyolali | P3: Manggis | Q3: =COUNTA('SRP Manggis Boyolali'!B3:B29)-3 -> 24 | R3: 8 | S3: =Q3-R3 -> 16 | T3: =S3+E3 -> 74
B4: Sragen | C4: Sukorejo | D4: Sambirejo | E4: =COUNTA(Sukorejo!B3:B61)-4 -> 55 | F4: =Sukorejo!O68 -> 20 | G4: =Sukorejo!O69 -> 29 | H4: =Sukorejo!H66-Sukorejo!H67 -> 22 | I4: =Sukorejo!I66-Sukorejo!I67 -> 25 | J4: =Sukorejo!J66-Sukorejo!J67 -> 31 | K4: =Sukorejo!K66-Sukorejo!K67 -> 31 | L4: =Sukorejo!L66-Sukorejo!L67 -> 28 | M4: =Sukorejo!M66-Sukorejo!M67 -> 21 | O4: Klaten | P4: Bangak | Q4: =COUNTA('SRP Bangak Boyolali '!B3:B37)-1 -> 34 | S4: =Q4-R4 -> 34 | T4: =S4 -> 34
A5: Tambahan | B5: Sragen | C5: Kliwonan | D5: Masaran | E5: =COUNTA(Kliwonan!B3:B45) -> 32 | H5: =Kliwonan!H47 -> 19 | I5: =Kliwonan!I47 -> 28 | J5: =Kliwonan!J47 -> 0 | K5: =Kliwonan!K47 -> 0 | L5: =Kliwonan!L47 -> 0 | M5: =Kliwonan!M47 -> 0 | P5: Sumber | Q5: =COUNTA('SRP Sumber Boyolali'!B3:B38)-1 -> 35 | S5: =Q5-R5 -> 35 | T5: =S5 -> 35
A6: Tambahan | B6: Klaten | C6: Jotangan | D6: Bayat | E6: =COUNTA(Jotangan!B3:B66) -> 50 | H6: =Jotangan!H67-Jotangan!H68 -> 28 | I6: =Jotangan!I67-Jotangan!I68 -> 27 | J6: =Jotangan!J67-Jotangan!J68 -> 22 | K6: =Jotangan!K67-Jotangan!K68 -> 23 | L6: =Jotangan!L67-Jotangan!L68 -> 25 | M6: =Jotangan!M67-Jotangan!M68 -> 28 | O6: Sragen | P6: Sukorejo | Q6: =COUNTA('SRP Sukorejo Sragen'!B3:B36)-2 -> 32 | R6: 11 | S6: =Q6-R6 -> 21 | T6: =S6+E4 -> 76
B7: Klaten | C7: Tawangrejo | D7: Bayat | E7: =COUNTA(Tawangrejo!B3:B32)-7 -> 23 | H7: =Tawangrejo!H49-Tawangrejo!H50 -> 23 | I7: =Tawangrejo!I49-Tawangrejo!I50 -> 11 | J7: =Tawangrejo!J49-Tawangrejo!J50 -> 15 | K7: =Tawangrejo!K49-Tawangrejo!K50 -> 0 | L7: =Tawangrejo!L49-Tawangrejo!L50 -> 0 | M7: =Tawangrejo!M49-Tawangrejo!M50 -> 0 | O7: Sragen | P7: Kliwonan | Q7: =COUNTA('SRP Kliwonan Sragen'!B3:B37)-1 -> 34 | S7: =Q7-R7 -> 34 | T7: =S7 -> 34
B8: Ngawi | C8: Geneng | D8: Geneng | E8: =COUNTA(Geneng!B3:B42) -> 35 | F8: =Geneng!N47 -> 18 | G8: =Geneng!N48 -> 23 | H8: =Geneng!H44-Geneng!H45 -> 24 | I8: =Geneng!I44-Geneng!I45 -> 30 | J8: =Geneng!J44-Geneng!J45 -> 23 | K8: =Geneng!K44-Geneng!K45 -> 22 | L8: =Geneng!L44-Geneng!L45 -> 24 | O8: Sragen | P8: Karangmalang | Q8: =COUNTA('SRP Karangmalang Sragen'!B3:B37)-2 -> 33 | S8: =Q8-R8 -> 33 | T8: =S8 -> 33
B9: Madiun | C9: Klumutan | D9: Saradan | E9: =COUNTA(Klumutan!B3:B72)-3 -> 63 | H9: =Klumutan!H73-Klumutan!H74 -> 22 | I9: =Klumutan!I73-Klumutan!I74 -> 25 | J9: =Klumutan!J73-Klumutan!J74 -> 25 | K9: =Klumutan!K73-Klumutan!K74 -> 22 | L9: =Klumutan!L73-Klumutan!L74 -> 18 | M9: =Klumutan!M73-Klumutan!M74 -> 37 | O9: Klaten | P9: Jotangan | Q9: =COUNTA('SRP Jotangan Boyolali'!B3:B35) -> 33 | R9: 22 | S9: =Q9-R9 -> 11 | T9: =S9+E6 -> 61
B10: TOTAL | E10: =SUM(E3:E9) -> 316 | F10: =SUM(F3:F9) -> 54 | G10: =SUM(G3:G9) -> 73 | H10: =SUM(H3:H9) -> 164 | I10: =SUM(I3:I9) -> 177 | J10: =SUM(J3:J9) -> 152 | K10: =SUM(K3:K9) -> 116 | L10: =SUM(L3:L9) -> 123 | M10: =SUM(M3:M9) -> 120 | N10: =SUM(H10:M10) -> 852 | O10: Ngawi | P10: Geneng | Q10: =COUNTA('SRP Geneng Ngawi'!B3:B34) -> 32 | S10: =Q10-R10 -> 32 | T10: =S10 -> 32
O11: Madiun | P11: Klumutan | Q11: =COUNTA('SRP Klumutan Madiun'!B3:B29)-1 -> 26 | R11: 12 | S11: =Q11-R11 -> 14 | T11: =S11+E9 -> 77
O12: Klaten | P12: Pogung | S12: =COUNTA('SRP Pogung Klaten'!B3:B35)-1 -> 32 | T12: =S12 -> 32
F13: Manggis | G13: Klumutan | H13: Jotangan | I13: Sukorejo | J13: Kliwonan | K13: Tawangrejo | L13: Geneng | O13: Boyolali | P13: Mojo | S13: ='SRP Mojo Boyolali'!D42 -> 33 | T13: =S13 -> 33
B14: usia sama/dibawah 35 | E14: laki-laki | F14: =Manggis!F67 -> 2 | G14: =Klumutan!E76 -> 3 | H14: =Jotangan!E69 -> 0 | I14: =Sukorejo!E68 -> 1 | J14: =Kliwonan!E49 -> 1 | K14: =Tawangrejo!D51 -> 0 | L14: =Geneng!D47 -> 0 | O14: Klaten | P14: Dukuh | S14: ='SRP Bahat Klaten'!D48 -> 37 | T14: =S14 -> 37
E15: perempuan | F15: =Manggis!F68 -> 0 | G15: =Klumutan!E77 -> 4 | H15: =Jotangan!E70 -> 1 | I15: =Sukorejo!E69 -> 0 | J15: =Kliwonan!E50 -> 0 | K15: =Tawangrejo!D52 -> 0 | L15: =Geneng!D48 -> 0 | O15: Klaten | P15: Tawangrejo | S15: =COUNTA('SRP Tawangrejo'!B3:B43) -> 41 | T15: =S15 -> 41
B16: usia diatas 35 | E16: laki-laki | F16: =Manggis!F69 -> 36 | G16: =Klumutan!E78 -> 48 | H16: =Jotangan!E71 -> 39 | I16: =Sukorejo!E70 -> 39 | J16: =Kliwonan!E51 -> 22 | K16: =Tawangrejo!D53 -> 15 | L16: =Geneng!D49 -> 28 | O16: Madiun | P16: Sugihwaras | S16: =COUNTA('SRP Sugihwaras'!B3:B34) -> 32 | T16: =S16 -> 32
E17: perempuan | F17: =Manggis!F70 -> 20 | G17: =Klumutan!E79 -> 8 | H17: =Jotangan!E72 -> 10 | I17: =Sukorejo!E71 -> 15 | J17: =Kliwonan!E52 -> 9 | K17: =Tawangrejo!D54 -> 8 | L17: =Geneng!D50 -> 7
E18: Total | F18: =SUM(F14:F17) -> 58 | G18: =SUM(G14:G17) -> 63 | H18: =SUM(H14:H17) -> 50 | I18: =SUM(I14:I17) -> 55 | J18: =SUM(J14:J17) -> 32 | K18: =SUM(K14:K17) -> 23 | L18: =SUM(L14:L17) -> 35 | P18: TOTAL | Q18: =SUM(Q3:Q13) -> 283 | R18: =SUM(R3:R11) -> 53 | S18: =SUM(S3:S16) -> 405 | T18: =SUM(T3:T16) -> 631
T19: =1340+T15+T16 -> 1413
T20: =T19+298 -> 1711 | U20: =T20-1800 -> -89
T22: Update OR | U22: Report SA
S23: 2025-2026 | T23: =819+S18 -> 1224 | U23: =819+442 -> 1261
S24: SL 2026 | T24: 316 | U24: 316
S25: Total | T25: =SUM(T23:T24) -> 1540 | U25: =SUM(U23:U24) -> 1577
S26: Indirect 2026 | T26: 220 | U26: 220
S27: Gap | T27: =(T25+T26)-1800 -> -40 | U27: =(U25+U26)-1800 -> -3

Sheet Manggis
B1: Name | C1: VF | D1: Full Name | G1: Luas Lahan (m2) | H1: Tanaman | I1: POC | J1: Pesnab | K1: Kompos | L1: Mulsa | M1: Jarwo | N1: Sex | O1: Age | P1: Date / Field School | X1: Grafik Total | AA1: sparkline
E2: Alamat | F2: Kelompok | P2: 46120 | Q2: 46134 | R2: 6 Mei 26 | S2: 28 Mei 26 | T2: 46184 | U2: 46198 | V2: Sum of participants | W2: Percentage of attendance | Y2: Training SRP | AB2: Note
A3: 1 | B3: Juwono | E3: BPP Mojosongo | N3: Laki-laki | O3: Diatas 35 tahun | P3: 1 | R3: 1 | T3: 1 | U3: 1 | V3: =SUM(P3:U3) -> 4 | W3: =SUM(P3:U3)/6 -> 0.66666667 | X3: =REPT("||||||",V3) -> |||||||||||||||||||||||| | Y3: 1
A4: 2 | B4: Anastasia Caturina | E4: BPP Mojosongo | N4: Perempuan | O4: Diatas 35 tahun | P4: 1 | T4: 1 | U4: 1 | V4: =SUM(P4:U4) -> 3 | W4: =SUM(P4:U4)/6 -> 0.5 | X4: =REPT("||||||",V4) -> ||||||||||||||||||
A5: 3 | B5: Rahmad Yulianto | E5: BPP Mojosongo | N5: Laki-laki | O5: Diatas 35 tahun | P5: 1 | V5: =SUM(P5:U5) -> 1 | W5: =SUM(P5:U5)/6 -> 0.16666667 | X5: =REPT("||||||",V5) -> ||||||
A6: 4 | B6: Anifah Eviyanti | E6: BPP Mojosongo | N6: Perempuan | O6: Diatas 35 tahun | P6: 1 | T6: 1 | V6: =SUM(P6:U6) -> 2 | W6: =SUM(P6:U6)/6 -> 0.33333333 | X6: =REPT("||||||",V6) -> ||||||||||||
A7: 5 | B7: Suryati | E7: Jambu wetan | N7: Perempuan | O7: Diatas 35 tahun | P7: 1 | Q7: 1 | R7: 1 | S7: 1 | T7: 1 | U7: 1 | V7: =SUM(P7:U7) -> 6 | W7: =SUM(P7:U7)/6 -> 1 | X7: =REPT("||||||",V7) -> ||||||||||||||||||||||||||||||||||||
A8: 6 | B8: Rini Rahayu | E8: Jambu wetan | N8: Perempuan | O8: Diatas 35 tahun | P8: 1 | R8: 1 | S8: 1 | T8: 1 | U8: 1 | V8: =SUM(P8:U8) -> 5 | W8: =SUM(P8:U8)/6 -> 0.83333333 | X8: =REPT("||||||",V8) -> ||||||||||||||||||||||||||||||
A9: 7 | B9: Nurti | E9: Jambu etan | N9: Perempuan | O9: Diatas 35 tahun | P9: 1 | V9: =SUM(P9:U9) -> 1 | W9: =SUM(P9:U9)/6 -> 0.16666667
A10: 8 | B10: Fitri Rahayu | E10: Bibis rejo | N10: Perempuan | O10: Diatas 35 tahun | P10: 1 | R10: 1 | T10: 1 | U10: 1 | V10: =SUM(P10:U10) -> 4 | W10: =SUM(P10:U10)/6 -> 0.66666667 | X10: =REPT("||||||",V10) -> ||||||||||||||||||||||||
A11: 9 | B11: Sunaryo | E11: Jambu wetan | N11: Laki-laki | O11: Diatas 35 tahun | P11: 1 | Q11: 1 | R11: 1 | S11: 1 | T11: 1 | U11: 1 | V11: =SUM(P11:U11) -> 6 | W11: =SUM(P11:U11)/6 -> 1 | X11: =REPT("||||||",V11) -> ||||||||||||||||||||||||||||||||||||
A12: 10 | B12: Darobi | E12: Jambu wetan | N12: Laki-laki | O12: Diatas 35 tahun | P12: 1 | Q12: 1 | R12: 1 | T12: 1 | U12: 1 | V12: =SUM(P12:U12) -> 5 | W12: =SUM(P12:U12)/6 -> 0.83333333 | X12: =REPT("||||||",V12) -> |||||||||||||||||||||||||||||| | Y12: 1
A13: 11 | B13: Santosa | E13: Jatirejo | N13: Laki-laki | O13: Diatas 35 tahun | P13: 1 | Q13: 1 | R13: 1 | T13: 1 | U13: 1 | V13: =SUM(P13:U13) -> 5 | W13: =SUM(P13:U13)/6 -> 0.83333333
A14: 12 | B14: Nur Sahid | E14: Dawar | N14: Laki-laki | O14: Diatas 35 tahun | P14: 1 | Q14: 1 | S14: 1 | T14: 1 | U14: 1 | V14: =SUM(P14:U14) -> 5 | W14: =SUM(P14:U14)/6 -> 0.83333333 | X14: =REPT("||||||",V14) -> |||||||||||||||||||||||||||||| | Y14: 1
A15: 13 | B15: Khoirul Fuad | E15: Dawar | N15: Laki-laki | O15: Diatas 35 tahun | P15: 1 | Q15: 1 | R15: 1 | S15: 1 | T15: 1 | U15: 1 | V15: =SUM(P15:U15) -> 6 | W15: =SUM(P15:U15)/6 -> 1 | X15: =REPT("||||||",V15) -> |||||||||||||||||||||||||||||||||||| | Y15: 1
A16: 14 | B16: Joko Susilo | E16: Gapoktan | N16: Laki-laki | O16: Diatas 35 tahun | P16: 1 | Q16: 1 | R16: 1 | S16: 1 | U16: 1 | V16: =SUM(P16:U16) -> 5 | W16: =SUM(P16:U16)/6 -> 0.83333333 | X16: =REPT("||||||",V16) -> |||||||||||||||||||||||||||||| | Y16: 1
A17: 15 | B17: Solekan | E17: Tani Harjo | N17: Laki-laki | O17: Sama / dibawah 35 tahun | P17: 1 | Q17: 1 | R17: 1 | S17: 1 | T17: 1 | U17: 1 | V17: =SUM(P17:U17) -> 6 | W17: =SUM(P17:U17)/6 -> 1 | X17: =REPT("||||||",V17) -> |||||||||||||||||||||||||||||||||||| | AC17: Male >35 yrs
A18: 16 | B18: Jarwanto | E18: Tani Makmur | N18: Laki-laki | O18: Diatas 35 tahun | P18: 1 | Q18: 1 | R18: 1 | S18: 1 | T18: 1 | U18: 1 | V18: =SUM(P18:U18) -> 6 | W18: =SUM(P18:U18)/6 -> 1 | X18: =REPT("||||||",V18) -> |||||||||||||||||||||||||||||||||||| | AC18: Female >35 yrs
A19: 17 | B19: Aris Salam | E19: Tani Subur | N19: Laki-laki | O19: Diatas 35 tahun | P19: 1 | Q19: 1 | R19: 1 | T19: 1 | U19: 1 | V19: =SUM(P19:U19) -> 5 | W19: =SUM(P19:U19)/6 -> 0.83333333 | X19: =REPT("||||||",V19) -> |||||||||||||||||||||||||||||| | AC19: Female <=35 yrs
A20: 18 | B20: Suyadi | E20: Tani Subur | N20: Laki-laki | O20: Diatas 35 tahun | P20: 1 | Q20: 1 | R20: 1 | T20: 1 | V20: =SUM(P20:U20) -> 4 | W20: =SUM(P20:U20)/6 -> 0.66666667 | X20: =REPT("||||||",V20) -> ||||||||||||||||||||||||
A21: 19 | B21: Sutomo | E21: Tani Subur | N21: Laki-laki | O21: Diatas 35 tahun | P21: 1 | Q21: 1 | R21: 1 | S21: 1 | T21: 1 | U21: 1 | V21: =SUM(P21:U21) -> 6 | W21: =SUM(P21:U21)/6 -> 1 | X21: =REPT("||||||",V21) -> ||||||||||||||||||||||||||||||||||||
A22: 20 | B22: Balmiri | E22: Jambu | N22: Laki-laki | O22: Diatas 35 tahun | P22: 1 | V22: =SUM(P22:U22) -> 1 | W22: =SUM(P22:U22)/6 -> 0.16666667 | X22: =REPT("||||||",V22) -> |||||| | AB22: 1 | AC22: jika peserta SL hadir
A23: 21 | B23: Sudadi | E23: Kiringan | N23: Laki-laki | O23: Diatas 35 tahun | P23: 1 | Q23: 1 | R23: 1 | S23: 1 | T23: 1 | U23: 1 | V23: =SUM(P23:U23) -> 6 | W23: =SUM(P23:U23)/6 -> 1 | X23: =REPT("||||||",V23) -> |||||||||||||||||||||||||||||||||||| | AB23: 0 | AC23: jika peserta SL tidak hadir
A24: 22 | B24: Widodo | E24: Kiringan | N24: Laki-laki | O24: Diatas 35 tahun | P24: 1 | Q24: 1 | R24: 1 | S24: 1 | U24: 1 | V24: =SUM(P24:U24) -> 5 | W24: =SUM(P24:U24)/6 -> 0.83333333 | X24: =REPT("||||||",V24) -> ||||||||||||||||||||||||||||||
A25: 23 | B25: Abdul Wakhid | E25: Kiringan | N25: Laki-laki | O25: Sama / dibawah 35 tahun | P25: 1 | R25: 1 | S25: 1 | U25: 1 | V25: =SUM(P25:U25) -> 4 | W25: =SUM(P25:U25)/6 -> 0.66666667 | X25: =REPT("||||||",V25) -> ||||||||||||||||||||||||
A26: 24 | B26: Mulyono | E26: Kiringan | N26: Laki-laki | O26: Diatas 35 tahun | P26: 1 | Q26: 1 | R26: 1 | T26: 1 | U26: 1 | V26: =SUM(P26:U26) -> 5 | W26: =SUM(P26:U26)/6 -> 0.83333333 | X26: =REPT("||||||",V26) -> ||||||||||||||||||||||||||||||
A27: 25 | B27: Joko Phihantoko | E27: Kiringan | N27: Laki-laki | O27: Diatas 35 tahun | P27: 1 | Q27: 1 | R27: 1 | T27: 1 | U27: 1 | V27: =SUM(P27:U27) -> 5 | W27: =SUM(P27:U27)/6 -> 0.83333333 | X27: =REPT("||||||",V27) -> ||||||||||||||||||||||||||||||
A28: 26 | B28: Sajino | E28: Tani Makmur | N28: Laki-laki | O28: Diatas 35 tahun | Q28: 1 | V28: =SUM(P28:U28) -> 1 | W28: =SUM(P28:U28)/6 -> 0.16666667
A29: 27 | B29: Harta | E29: Kiringan | N29: Laki-laki | O29: Diatas 35 tahun | Q29: 1 | R29: 1 | S29: 1 | T29: 1 | U29: 1 | V29: =SUM(P29:U29) -> 5 | W29: =SUM(P29:U29)/6 -> 0.83333333
A30: 28 | B30: Nurti Ambaryani | E30: Jambu Kulon | N30: Perempuan | O30: Diatas 35 tahun | Q30: 1 | R30: 1 | S30: 1 | U30: 1 | V30: =SUM(P30:U30) -> 4 | W30: =SUM(P30:U30)/6 -> 0.66666667
A31: 29 | B31: Rini R | E31: Jambu Kulon | N31: Perempuan | O31: Diatas 35 tahun | Q31: 1 | R31: 1 | V31: =SUM(P31:U31) -> 2 | W31: =SUM(P31:U31)/6 -> 0.33333333
A32: 30 | B32: Dalmini | E32: Tani Harjo | N32: Perempuan | O32: Diatas 35 tahun | Q32: 1 | R32: 1 | T32: 1 | U32: 1 | V32: =SUM(P32:U32) -> 4 | W32: =SUM(P32:U32)/6 -> 0.66666667
A33: 31 | B33: Sri Mulyani | E33: BPP Teras | N33: Perempuan | O33: Diatas 35 tahun | Q33: 1 | U33: 1 | V33: =SUM(P33:U33) -> 2 | W33: =SUM(P33:U33)/6 -> 0.33333333
A34: 32 | B34: Dwi Hartono | E34: BPP Teras | N34: Laki-laki | O34: Diatas 35 tahun | Q34: 1 | V34: =SUM(P34:U34) -> 1 | W34: =SUM(P34:U34)/6 -> 0.16666667
A35: 33 | B35: Jumadi | E35: BPP Teras | N35: Laki-laki | O35: Diatas 35 tahun | Q35: 1 | V35: =SUM(P35:U35) -> 1 | W35: =SUM(P35:U35)/6 -> 0.16666667
A36: 34 | B36: Supatdiman | E36: BPP Teras | N36: Laki-laki | O36: Diatas 35 tahun | Q36: 1 | V36: =SUM(P36:U36) -> 1 | W36: =SUM(P36:U36)/6 -> 0.16666667
A37: 35 | B37: Tafib Zen | E37: BPP Teras | N37: Laki-laki | O37: Diatas 35 tahun | Q37: 1 | V37: =SUM(P37:U37) -> 1 | W37: =SUM(P37:U37)/6 -> 0.16666667
A38: 36 | B38: Sukari | E38: Tani Harjo | N38: Laki-laki | O38: Diatas 35 tahun | Q38: 1 | V38: =SUM(P38:U38) -> 1 | W38: =SUM(P38:U38)/6 -> 0.16666667 | Y38: 1
A39: 37 | B39: Umiyati | E39: Tani Harjo | N39: Perempuan | O39: Diatas 35 tahun | Q39: 1 | R39: 1 | T39: 1 | U39: 1 | V39: =SUM(P39:U39) -> 4 | W39: =SUM(P39:U39)/6 -> 0.66666667
A40: 38 | B40: Dwijo | E40: Tani Harjo | N40: Laki-laki | O40: Diatas 35 tahun | Q40: 1 | R40: 1 | S40: 1 | T40: 1 | U40: 1 | V40: =SUM(P40:U40) -> 5 | W40: =SUM(P40:U40)/6 -> 0.83333333
...

Sheet Sukorejo
B1: Name | E1: Luas Lahan (m2) | F1: Sex | G1: Age | H1: Date / Field School | P1: Grafik Total
C2: Alamat | H2: 46127 | I2: 46141 | J2: 13 Mei 2026 | K2: 28 Mei 26 | L2: 46194 | M2: 46211 | N2: Sum of participants | O2: Percentage of attendance | Q2: TrainingSRP | U2: Note
A3: 1 | B3: Sis Pardi | C3: Sri Rejeki | D3: 0812 27135 279 | F3: Laki-laki | G3: Diatas 35 tahun | H3: 1 | I3: 1 | J3: 1 | K3: 1 | N3: =SUM(H3:L3) -> 4 | O3: =SUM(H3:L3)/5 -> 0.8 | P3: =REPT("||||||",N3) -> |||||||||||||||||||||||| | U3: 1 | V3: jika peserta SL hadir
A4: 2 | B4: Gunarto | C4: Margo Rukun I | F4: Laki-laki | G4: Diatas 35 tahun | H4: 1 | I4: 1 | N4: =SUM(H4:L4) -> 2 | O4: =SUM(H4:L4)/5 -> 0.4 | P4: =REPT("||||||",N4) -> |||||||||||| | Q4: 1
A5: 3 | B5: Sularsih | C5: Sri Makmur | F5: Perempuan | G5: Diatas 35 tahun | H5: 1 | J5: 1 | N5: =SUM(H5:L5) -> 2 | O5: =SUM(H5:L5)/5 -> 0.4 | P5: =REPT("||||||",N5) -> ||||||||||||
A6: 4 | B6: Sunah Priyanti | C6: Margo Rukun 2 | D6: 0857 0173 1107 | F6: Perempuan | G6: Diatas 35 tahun | H6: 1 | J6: 1 | K6: 1 | L6: 1 | M6: 1 | N6: =SUM(H6:L6) -> 4 | O6: =SUM(H6:L6)/5 -> 0.8 | P6: =REPT("||||||",N6) -> ||||||||||||||||||||||||
A7: 5 | B7: Yuni | C7: Margo Rukun 2 | D7: 0831 9044 6227 | F7: Perempuan | G7: Diatas 35 tahun | H7: 1 | I7: 1 | J7: 1 | K7: 1 | L7: 1 | M7: 1 | N7: =SUM(H7:L7) -> 5 | O7: =SUM(H7:L7)/5 -> 1 | P7: =REPT("||||||",N7) -> ||||||||||||||||||||||||||||||
A8: 6 | B8: Santo | C8: Gemah Ripah | F8: Laki-laki | G8: Diatas 35 tahun | H8: 1 | I8: 1 | N8: =SUM(H8:L8) -> 2 | O8: =SUM(H8:L8)/5 -> 0.4 | P8: =REPT("||||||",N8) -> |||||||||||| | Q8: 1
A9: 7 | B9: Hartanto | C9: Sukorejo | D9: 081 3396 8239 | F9: Laki-laki | G9: Diatas 35 tahun | H9: 1 | I9: 1 | K9: 1 | L9: 1 | M9: 1 | N9: =SUM(H9:L9) -> 4 | O9: =SUM(H9:L9)/5 -> 0.8 | P9: =REPT("||||||",N9) -> ||||||||||||||||||||||||
A10: 8 | B10: Juyono | C10: Margo Rukun 2 | F10: Laki-laki | G10: Diatas 35 tahun | H10: 1 | N10: =SUM(H10:L10) -> 1 | O10: =SUM(H10:L10)/5 -> 0.2 | P10: =REPT("||||||",N10) -> ||||||
A11: 9 | B11: Ali Silsa | C11: PPL | F11: Laki-laki | G11: Diatas 35 tahun | H11: 1 | M11: 1 | N11: =SUM(H11:L11) -> 1 | O11: =SUM(H11:L11)/5 -> 0.2 | P11: =REPT("||||||",N11) -> ||||||
A12: 10 | B12: Markatam | C12: PPL | F12: Laki-laki | G12: Diatas 35 tahun | H12: 1 | N12: =SUM(H12:L12) -> 1 | O12: =SUM(H12:L12)/5 -> 0.2 | P12: =REPT("||||||",N12) -> ||||||
A13: 11 | B13: Danang Tri Utomo | C13: Rikolto | F13: Laki-laki | G13: Diatas 35 tahun | H13: 1 | I13: 1 | J13: 1 | M13: 1 | N13: =SUM(H13:M13) -> 4 | O13: =SUM(H13:L13)/5 -> 0.6 | P13: =REPT("||||||",N13) -> ||||||||||||||||||||||||
A14: 12 | B14: Sri Hartati | C14: Sri Rejeki | D14: 082138504994 | F14: Perempuan | G14: Diatas 35 tahun | H14: 1 | I14: 1 | J14: 1 | K14: 1 | L14: 1 | M14: 1 | N14: =SUM(H14:M14) -> 6 | O14: =SUM(H14:L14)/5 -> 1 | P14: =REPT("||||||",N14) -> |||||||||||||||||||||||||||||||||||| | U14: 0 | V14: jika peserta SL tidak hadir
A15: 13 | B15: Sulastri | C15: Sri Rejeki | D15: 0857 7537 3669 | F15: Perempuan | G15: Diatas 35 tahun | H15: 1 | I15: 1 | J15: 1 | K15: 1 | L15: 1 | M15: 1 | N15: =SUM(H15:L15) -> 5 | O15: =SUM(H15:L15)/5 -> 1 | P15: =REPT("||||||",N15) -> ||||||||||||||||||||||||||||||
A16: 14 | B16: Bandi | C16: Sri Rejeki | D16: 0813 2866 8911 | F16: Laki-laki | G16: Diatas 35 tahun | H16: 1 | I16: 1 | J16: 1 | K16: 1 | L16: 1 | M16: 1 | N16: =SUM(H16:L16) -> 5 | O16: =SUM(H16:L16)/5 -> 1 | P16: =REPT("||||||",N16) -> |||||||||||||||||||||||||||||| | Q16: 1
A17: 15 | B17: Sadi | C17: Sri Rejeki | F17: Laki-laki | G17: Diatas 35 tahun | H17: 1 | I17: 1 | K17: 1 | L17: 1 | M17: 1 | N17: =SUM(H17:L17) -> 4 | O17: =SUM(H17:L17)/5 -> 0.8 | P17: =REPT("||||||",N17) -> |||||||||||||||||||||||| | Q17: 1
A18: 16 | B18: Pujiwiyono | C18: Sri Rejeki | F18: Laki-laki | G18: Diatas 35 tahun | H18: 1 | I18: 1 | J18: 1 | K18: 1 | L18: 1 | M18: 1 | N18: =SUM(H18:M18) -> 6 | O18: =SUM(H18:L18)/5 -> 1 | P18: =REPT("||||||",N18) -> ||||||||||||||||||||||||||||||||||||
A19: 17 | B19: Widodo | C19: Sri Rejeki | D19: 0822 2083 3137 | F19: Laki-laki | G19: Sama / dibawah 35 tahun | H19: 1 | I19: 1 | J19: 1 | K19: 1 | N19: =SUM(H19:L19) -> 4 | O19: =SUM(H19:L19)/5 -> 0.8 | P19: =REPT("||||||",N19) -> |||||||||||||||||||||||| | Q19: 1
A20: 18 | B20: Ni Suida | C20: PPL | F20: Perempuan | G20: Diatas 35 tahun | H20: 1 | N20: =SUM(H20:L20) -> 1 | O20: =SUM(H20:L20)/5 -> 0.2 | P20: =REPT("||||||",N20) -> ||||||
A21: 19 | B21: Sriyana | C21: Poktan | F21: Perempuan | G21: Diatas 35 tahun | H21: 1 | N21: =SUM(H21:L21) -> 1 | O21: =SUM(H21:L21)/5 -> 0.2 | P21: =REPT("||||||",N21) -> ||||||
A22: 20 | B22: Supriyanto | C22: Sri Rejeki | D22: 0822 4133 0659 | F22: Laki-laki | G22: Diatas 35 tahun | H22: 1 | I22: 1 | J22: 1 | K22: 1 | L22: 1 | M22: 1 | N22: =SUM(H22:L22) -> 5 | O22: =SUM(H22:L22)/5 -> 1 | P22: =REPT("||||||",N22) -> ||||||||||||||||||||||||||||||
A23: 21 | B23: Sumarno | C23: Sri Rejeki | F23: Laki-laki | G23: Diatas 35 tahun | H23: 1 | I23: 1 | J23: 1 | L23: 1 | N23: =SUM(H23:L23) -> 4 | O23: =SUM(H23:L23)/5 -> 0.8 | P23: =REPT("||||||",N23) -> |||||||||||||||||||||||| | Q23: 1
A24: 22 | B24: Mugono | C24: Sri Rejeki | D24: 81226100255 | F24: Laki-laki | G24: Diatas 35 tahun | H24: 1 | I24: 1 | K24: 1 | L24: 1 | M24: 1 | N24: =SUM(H24:L24) -> 4 | O24: =SUM(H24:L24)/5 -> 0.8 | P24: =REPT("||||||",N24) -> |||||||||||||||||||||||| | Q24: 1
A25: 23 | B25: Patmasuwido | C25: Sri Rejeki | F25: Laki-laki | G25: Diatas 35 tahun | H25: 1 | I25: 1 | J25: 1 | K25: 1 | L25: 1 | N25: =SUM(H25:L25) -> 5 | O25: =SUM(H25:L25)/5 -> 1 | P25: =REPT("||||||",N25) -> ||||||||||||||||||||||||||||||
A26: 24 | B26: Kardi | C26: Sri Rejeki | F26: Laki-laki | G26: Diatas 35 tahun | H26: 1 | I26: 1 | J26: 1 | K26: 1 | L26: 1 | N26: =SUM(H26:L26) -> 5 | O26: =SUM(H26:L26)/5 -> 1 | P26: =REPT("||||||",N26) -> |||||||||||||||||||||||||||||| | V26: Female <35 yrs
A27: 25 | B27: Haribowo | C27: Sukorejo | D27: 0853-2566-6400 | F27: Laki-laki | G27: Diatas 35 tahun | H27: 1 | I27: 1 | J27: 1 | K27: 1 | N27: =SUM(H27:L27) -> 4 | O27: =SUM(H27:L27)/5 -> 0.8 | P27: =REPT("||||||",N27) -> |||||||||||||||||||||||| | V27: Female >= 35 yrs
A28: 26 | B28: Nanik | C28: Sri Rejeki | F28: Perempuan | G28: Diatas 35 tahun | H28: 1 | I28: 1 | J28: 1 | L28: 1 | M28: 1 | N28: =SUM(H28:L28) -> 4 | O28: =SUM(H28:L28)/5 -> 0.8 | P28: =REPT("||||||",N28) -> |||||||||||||||||||||||| | Q28: 1
A29: 27 | B29: Hartini | C29: Margo RukunI | D29: 0819 12566 318 | F29: Perempuan | G29: Diatas 35 tahun | J29: 1 | K29: 1 | L29: 1 | N29: =SUM(H29:L29) -> 3 | O29: =SUM(H29:L29)/5 -> 0.6 | P29: =REPT("||||||",N29) -> |||||||||||||||||| | Q29: 1
A30: 28 | B30: Muji Rahayu | C30: Sri Makmur | D30: 0878 7984 7546 | F30: Perempuan | G30: Diatas 35 tahun | J30: 1 | K30: 1 | L30: 1 | M30: 1 | N30: =SUM(H30:L30) -> 3 | O30: =SUM(H30:L30)/5 -> 0.6 | P30: =REPT("||||||",N30) -> ||||||||||||||||||
A31: 29 | B31: Harni | C31: Sri Rejeki | F31: Perempuan | G31: Diatas 35 tahun | J31: 1 | K31: 1 | L31: 1 | N31: =SUM(H31:L31) -> 3 | O31: =SUM(H31:L31)/5 -> 0.6 | P31: =REPT("||||||",N31) -> |||||||||||||||||| | V31: Male >=35 yrs
A32: 30 | B32: Kariyem | C32: Margo Rukun 2 | F32: Perempuan | G32: Diatas 35 tahun | J32: 1 | N32: =SUM(H32:L32) -> 1 | O32: =SUM(H32:L32)/5 -> 0.2 | P32: =REPT("||||||",N32) -> ||||||
A33: 31 | B33: Suginem | C33: Margo Rukun I | D33: 0823 2252 5206 | F33: Perempuan | G33: Diatas 35 tahun | I33: 1 | J33: 1 | K33: 1 | L33: 1 | M33: 1 | N33: =SUM(H33:L33) -> 4 | O33: =SUM(H33:L33)/5 -> 0.8 | P33: =REPT("||||||",N33) -> ||||||||||||||||||||||||
A34: 32 | B34: Ayuk Parmawati | C34: Sri Rejeki | F34: Perempuan | G34: Diatas 35 tahun | J34: 1 | N34: =SUM(H34:L34) -> 1 | O34: =SUM(H34:L34)/5 -> 0.2 | P34: =REPT("||||||",N34) -> ||||||
A35: 33 | B35: Andrian | C35: Sri Rejeki | D35: 0877 4313 5954 | F35: Laki-laki | G35: Diatas 35 tahun | J35: 1 | K35: 1 | L35: 1 | M35: 1 | N35: =SUM(H35:M35) -> 4 | O35: =SUM(H35:L35)/5 -> 0.6 | P35: =REPT("||||||",N35) -> ||||||||||||||||||||||||
A36: 34 | B36: Surono | C36: Sri Rejeki | F36: Laki-laki | G36: Diatas 35 tahun | J36: 1 | N36: =SUM(H36:L36) -> 1 | O36: =SUM(H36:L36)/5 -> 0.2 | P36: =REPT("||||||",N36) -> ||||||
A37: 35 | B37: Suyono | C37: Margo Rukun 2 | F37: Laki-laki | G37: Diatas 35 tahun | I37: 1 | J37: 1 | K37: 1 | L37: 1 | M37: 1 | N37: =SUM(H37:L37) -> 4 | O37: =SUM(H37:L37)/5 -> 0.8 | P37: =REPT("||||||",N37) -> |||||||||||||||||||||||| | Q37: 1
A38: 36 | B38: Suroso | C38: Margo Rukun 1 | D38: 0877-7232-6858 | F38: Laki-laki | G38: Diatas 35 tahun | J38: 1 | K38: 1 | L38: 1 | M38: 1 | N38: =SUM(H38:L38) -> 3 | O38: =SUM(H38:L38)/5 -> 0.6 | P38: =REPT("||||||",N38) -> ||||||||||||||||||
A39: 37 | B39: Mujiyono | C39: Sri Rejeki | F39: Laki-laki | G39: Diatas 35 tahun | J39: 1 | L39: 1 | N39: =SUM(H39:L39) -> 2 | O39: =SUM(H39:L39)/5 -> 0.4 | P39: =REPT("||||||",N39) -> ||||||||||||
A40: 38 | B40: Karji | C40: Sri Rejeki | F40: Laki-laki | G40: Diatas 35 tahun | J40: 1 | N40: =SUM(H40:L40) -> 1 | O40: =SUM(H40:L40)/5 -> 0.2 | P40: =REPT("||||||",N40) -> ||||||
...

Sheet Kliwonan
B1: Name | E1: Luas Lahan (m2) | F1: Sex | G1: Age | H1: Date / Field School | O1: Grafik | P1: Grafik Total
C2: Alamat | D2: Non Petani | H2: 46286 | I2: 2 Okt 26 | M2: Sum of participants | N2: Percentage of attendance | T2: Note
A3: 1 | B3: Samiyem | C3: Bayur | F3: Laki-laki | G3: Diatas 35 tahun | I3: 1 | M3: =SUM(H3:L3) -> 1 | N3: =SUM(H3:L3)/4 -> 0.25 | P3: =REPT("||||||",M3) -> |||||| | T3: 1 | U3: jika peserta SL hadir
A4: 2 | B4: Ali Sayogo | C4: Kliwonan | F4: Laki-laki | G4: Diatas 35 tahun | H4: 1 | I4: 1 | M4: =SUM(H4:L4) -> 2 | N4: =SUM(H4:L4)/4 -> 0.5 | P4: =REPT("|",M4) -> ||
A5: 3 | B5: Sutarno | C5: Kuyang | F5: Perempuan | G5: Diatas 35 tahun | H5: 1 | I5: 1 | M5: =SUM(H5:L5) -> 2 | N5: =SUM(H5:L5)/4 -> 0.5 | P5: =REPT("||||||",M5) -> ||||||||||||
A6: 4 | B6: Sunardi | C6: Sidodadi | F6: Perempuan | G6: Diatas 35 tahun | I6: 1 | M6: =SUM(H6:L6) -> 1 | N6: =SUM(H6:L6)/4 -> 0.25 | P6: =REPT("|",M6) -> |
A7: 5 | B7: Abadi | C7: Bayur | F7: Perempuan | G7: Diatas 35 tahun | I7: 1 | M7: =SUM(H7:L7) -> 1 | N7: =SUM(H7:L7)/4 -> 0.25 | P7: =REPT("||||||",M7) -> ||||||
A8: 6 | B8: Arif Harianto | C8: Kuyang | F8: Laki-laki | G8: Diatas 35 tahun | H8: 1 | I8: 1 | M8: =SUM(H8:L8) -> 2 | N8: =SUM(H8:L8)/4 -> 0.5
A9: 7 | B9: Darno | C9: Kuyang | F9: Laki-laki | G9: Diatas 35 tahun | H9: 1 | I9: 1 | M9: =SUM(H9:L9) -> 2 | N9: =SUM(H9:L9)/4 -> 0.5
A10: 8 | B10: Owang H | C10: Kuyang | F10: Laki-laki | G10: Diatas 35 tahun | I10: 1 | M10: =SUM(H10:L10) -> 1 | N10: =SUM(H10:L10)/4 -> 0.25 | P10: =REPT("||||||",M10) -> ||||||
A11: 9 | B11: Widodo | C11: Kliwonan | F11: Laki-laki | G11: Diatas 35 tahun | H11: 1 | I11: 1 | M11: =SUM(H11:L11) -> 2 | N11: =SUM(H11:L11)/4 -> 0.5 | P11: =REPT("|",M11) -> ||
A12: 10 | B12: Warsito | C12: Kliwonan | F12: Laki-laki | G12: Diatas 35 tahun | H12: 1 | I12: 1 | M12: =SUM(H12:L12) -> 2 | N12: =SUM(H12:L12)/4 -> 0.5 | P12: =REPT("||||||",M12) -> ||||||||||||
A13: 11 | B13: Jumari | C13: Karang Malang | F13: Laki-laki | G13: Diatas 35 tahun | H13: 1 | I13: 1 | M13: =SUM(H13:L13) -> 2 | N13: =SUM(H13:L13)/4 -> 0.5 | P13: =REPT("||||||",M13) -> ||||||||||||
A14: 12 | B14: Gunadi | C14: Karang Malang | F14: Perempuan | G14: Diatas 35 tahun | H14: 1 | I14: 1 | M14: =SUM(H14:L14) -> 2 | N14: =SUM(H14:L14)/4 -> 0.5 | P14: =REPT("||||||",M14) -> |||||||||||| | T14: 0 | U14: jika peserta SL tidak hadir
A15: 13 | B15: Nurhadi | C15: Gelang | F15: Perempuan | G15: Diatas 35 tahun | H15: 1 | I15: 1 | M15: =SUM(H15:L15) -> 2 | N15: =SUM(H15:L15)/4 -> 0.5 | P15: =REPT("|",M15) -> ||
A16: 14 | B16: Sastro SGT | C16: Pengkol | F16: Laki-laki | G16: Diatas 35 tahun | I16: 1 | M16: =SUM(H16:L16) -> 1 | N16: =SUM(H16:L16)/4 -> 0.25 | P16: =REPT("|",M16) -> |
A17: 15 | B17: Sukamdi | C17: Kliwonan | F17: Laki-laki | G17: Diatas 35 tahun | I17: 1 | N17: =SUM(H17:L17)/4 -> 0.25
